I'm sorry, but an uncaught exception occurred.

While running game code:
  File "game/script.rpy", line 63, in script
    osi "Ohh, come on! Don't be such a meanie."
Exception: Sayer 'osi' is not defined.

-- Full Traceback ------------------------------------------------------------

Full traceback:
  File "game/script.rpy", line 63, in script
    osi "Ohh, come on! Don't be such a meanie."
  File "C:\Users\Afos\Documents\renpy-8.3.4-sdk\renpy\ast.py", line 2579, in execute
    Say.execute(self)
  File "C:\Users\Afos\Documents\renpy-8.3.4-sdk\renpy\ast.py", line 581, in execute
    who = eval_who(self.who, self.who_fast)
  File "C:\Users\Afos\Documents\renpy-8.3.4-sdk\renpy\ast.py", line 470, in eval_who
    raise Exception("Sayer '%s' is not defined." % who)
Exception: Sayer 'osi' is not defined.

Windows-10-10.0.19045 AMD64
Ren'Py 8.3.4.24120703
GGJ_PROTO1 1.0
Sat Jan 25 07:56:49 2025
